[2023-03-01 12:06:41,909] {taskinstance.py:877} INFO - Dependencies all met for <TaskInstance: first_dag.task_2 2021-08-10T00:00:00+00:00 [queued]>
[2023-03-01 12:06:42,143] {taskinstance.py:877} INFO - Dependencies all met for <TaskInstance: first_dag.task_2 2021-08-10T00:00:00+00:00 [queued]>
[2023-03-01 12:06:42,152] {taskinstance.py:1068} INFO - 
--------------------------------------------------------------------------------
[2023-03-01 12:06:42,173] {taskinstance.py:1069} INFO - Starting attempt 1 of 6
[2023-03-01 12:06:42,187] {taskinstance.py:1070} INFO - 
--------------------------------------------------------------------------------
[2023-03-01 12:06:42,440] {taskinstance.py:1089} INFO - Executing <Task(BashOperator): task_2> on 2021-08-10T00:00:00+00:00
[2023-03-01 12:06:42,471] {standard_task_runner.py:52} INFO - Started process 705 to run task
[2023-03-01 12:06:42,579] {standard_task_runner.py:76} INFO - Running: ['airflow', 'tasks', 'run', 'first_dag', 'task_2', '2021-08-10T00:00:00+00:00', '--job-id', '118', '--pool', 'default_pool', '--raw', '--subdir', 'DAGS_FOLDER/01_hello.py', '--cfg-path', '/tmp/tmpa65lcidr', '--error-file', '/tmp/tmplvfr6srn']
[2023-03-01 12:06:42,620] {standard_task_runner.py:77} INFO - Job 118: Subtask task_2
[2023-03-01 12:06:43,395] {logging_mixin.py:104} INFO - Running <TaskInstance: first_dag.task_2 2021-08-10T00:00:00+00:00 [running]> on host abe4c4997ef7
[2023-03-01 12:06:43,746] {taskinstance.py:1283} INFO - Exporting the following env vars:
AIRFLOW_CTX_DAG_OWNER=dataheroes
AIRFLOW_CTX_DAG_ID=first_dag
AIRFLOW_CTX_TASK_ID=task_2
AIRFLOW_CTX_EXECUTION_DATE=2021-08-10T00:00:00+00:00
AIRFLOW_CTX_DAG_RUN_ID=scheduled__2021-08-10T00:00:00+00:00
[2023-03-01 12:06:43,750] {bash.py:135} INFO - Tmp dir root location: 
 /tmp
[2023-03-01 12:06:43,766] {bash.py:158} INFO - Running command: Hello Task 2
[2023-03-01 12:06:43,877] {bash.py:169} INFO - Output:
[2023-03-01 12:06:44,201] {bash.py:173} INFO - bash: Hello: command not found
[2023-03-01 12:06:44,227] {bash.py:177} INFO - Command exited with return code 127
[2023-03-01 12:06:44,374] {taskinstance.py:1482} ERROR - Task failed with exception
Traceback (most recent call last):
  File "/home/airflow/.local/lib/python3.6/site-packages/airflow/models/taskinstance.py", line 1138, in _run_raw_task
    self._prepare_and_execute_task_with_callbacks(context, task)
  File "/home/airflow/.local/lib/python3.6/site-packages/airflow/models/taskinstance.py", line 1311, in _prepare_and_execute_task_with_callbacks
    result = self._execute_task(context, task_copy)
  File "/home/airflow/.local/lib/python3.6/site-packages/airflow/models/taskinstance.py", line 1341, in _execute_task
    result = task_copy.execute(context=context)
  File "/home/airflow/.local/lib/python3.6/site-packages/airflow/operators/bash.py", line 180, in execute
    raise AirflowException('Bash command failed. The command returned a non-zero exit code.')
airflow.exceptions.AirflowException: Bash command failed. The command returned a non-zero exit code.
[2023-03-01 12:06:44,454] {taskinstance.py:1532} INFO - Marking task as UP_FOR_RETRY. dag_id=first_dag, task_id=task_2, execution_date=20210810T000000, start_date=20230301T120641, end_date=20230301T120644
[2023-03-01 12:06:44,753] {local_task_job.py:146} INFO - Task exited with return code 1
