[2023-03-01 12:17:07,860] {taskinstance.py:877} INFO - Dependencies all met for <TaskInstance: first_dag.task_2 2021-08-01T00:00:00+00:00 [queued]>
[2023-03-01 12:17:08,024] {taskinstance.py:877} INFO - Dependencies all met for <TaskInstance: first_dag.task_2 2021-08-01T00:00:00+00:00 [queued]>
[2023-03-01 12:17:08,025] {taskinstance.py:1068} INFO - 
--------------------------------------------------------------------------------
[2023-03-01 12:17:08,026] {taskinstance.py:1069} INFO - Starting attempt 6 of 6
[2023-03-01 12:17:08,027] {taskinstance.py:1070} INFO - 
--------------------------------------------------------------------------------
[2023-03-01 12:17:08,234] {taskinstance.py:1089} INFO - Executing <Task(BashOperator): task_2> on 2021-08-01T00:00:00+00:00
[2023-03-01 12:17:08,282] {standard_task_runner.py:52} INFO - Started process 3310 to run task
[2023-03-01 12:17:08,392] {standard_task_runner.py:76} INFO - Running: ['airflow', 'tasks', 'run', 'first_dag', 'task_2', '2021-08-01T00:00:00+00:00', '--job-id', '641', '--pool', 'default_pool', '--raw', '--subdir', 'DAGS_FOLDER/01_hello.py', '--cfg-path', '/tmp/tmpjtd9nla4', '--error-file', '/tmp/tmp8c0fvge4']
[2023-03-01 12:17:08,419] {standard_task_runner.py:77} INFO - Job 641: Subtask task_2
[2023-03-01 12:17:08,870] {logging_mixin.py:104} INFO - Running <TaskInstance: first_dag.task_2 2021-08-01T00:00:00+00:00 [running]> on host abe4c4997ef7
[2023-03-01 12:17:09,274] {taskinstance.py:1283} INFO - Exporting the following env vars:
AIRFLOW_CTX_DAG_OWNER=dataheroes
AIRFLOW_CTX_DAG_ID=first_dag
AIRFLOW_CTX_TASK_ID=task_2
AIRFLOW_CTX_EXECUTION_DATE=2021-08-01T00:00:00+00:00
AIRFLOW_CTX_DAG_RUN_ID=scheduled__2021-08-01T00:00:00+00:00
[2023-03-01 12:17:09,276] {bash.py:135} INFO - Tmp dir root location: 
 /tmp
[2023-03-01 12:17:09,292] {bash.py:158} INFO - Running command: Hello Task 2
[2023-03-01 12:17:09,373] {bash.py:169} INFO - Output:
[2023-03-01 12:17:09,625] {bash.py:173} INFO - bash: Hello: command not found
[2023-03-01 12:17:09,648] {bash.py:177} INFO - Command exited with return code 127
[2023-03-01 12:17:09,707] {taskinstance.py:1482} ERROR - Task failed with exception
Traceback (most recent call last):
  File "/home/airflow/.local/lib/python3.6/site-packages/airflow/models/taskinstance.py", line 1138, in _run_raw_task
    self._prepare_and_execute_task_with_callbacks(context, task)
  File "/home/airflow/.local/lib/python3.6/site-packages/airflow/models/taskinstance.py", line 1311, in _prepare_and_execute_task_with_callbacks
    result = self._execute_task(context, task_copy)
  File "/home/airflow/.local/lib/python3.6/site-packages/airflow/models/taskinstance.py", line 1341, in _execute_task
    result = task_copy.execute(context=context)
  File "/home/airflow/.local/lib/python3.6/site-packages/airflow/operators/bash.py", line 180, in execute
    raise AirflowException('Bash command failed. The command returned a non-zero exit code.')
airflow.exceptions.AirflowException: Bash command failed. The command returned a non-zero exit code.
[2023-03-01 12:17:09,737] {taskinstance.py:1532} INFO - Marking task as FAILED. dag_id=first_dag, task_id=task_2, execution_date=20210801T000000, start_date=20230301T121707, end_date=20230301T121709
[2023-03-01 12:17:10,156] {local_task_job.py:146} INFO - Task exited with return code 1
