[2023-03-01 12:03:39,201] {taskinstance.py:877} INFO - Dependencies all met for <TaskInstance: first_dag.task_1 2021-08-13T00:00:00+00:00 [queued]>
[2023-03-01 12:03:39,237] {taskinstance.py:877} INFO - Dependencies all met for <TaskInstance: first_dag.task_1 2021-08-13T00:00:00+00:00 [queued]>
[2023-03-01 12:03:39,239] {taskinstance.py:1068} INFO - 
--------------------------------------------------------------------------------
[2023-03-01 12:03:39,240] {taskinstance.py:1069} INFO - Starting attempt 3 of 6
[2023-03-01 12:03:39,240] {taskinstance.py:1070} INFO - 
--------------------------------------------------------------------------------
[2023-03-01 12:03:39,276] {taskinstance.py:1089} INFO - Executing <Task(BashOperator): task_1> on 2021-08-13T00:00:00+00:00
[2023-03-01 12:03:39,282] {standard_task_runner.py:52} INFO - Started process 428 to run task
[2023-03-01 12:03:39,291] {standard_task_runner.py:76} INFO - Running: ['airflow', 'tasks', 'run', 'first_dag', 'task_1', '2021-08-13T00:00:00+00:00', '--job-id', '82', '--pool', 'default_pool', '--raw', '--subdir', 'DAGS_FOLDER/01_hello.py', '--cfg-path', '/tmp/tmpiv7p8h79', '--error-file', '/tmp/tmpy2k2fcdt']
[2023-03-01 12:03:39,293] {standard_task_runner.py:77} INFO - Job 82: Subtask task_1
[2023-03-01 12:03:39,395] {logging_mixin.py:104} INFO - Running <TaskInstance: first_dag.task_1 2021-08-13T00:00:00+00:00 [running]> on host abe4c4997ef7
[2023-03-01 12:03:39,484] {taskinstance.py:1283} INFO - Exporting the following env vars:
AIRFLOW_CTX_DAG_OWNER=dataheroes
AIRFLOW_CTX_DAG_ID=first_dag
AIRFLOW_CTX_TASK_ID=task_1
AIRFLOW_CTX_EXECUTION_DATE=2021-08-13T00:00:00+00:00
AIRFLOW_CTX_DAG_RUN_ID=scheduled__2021-08-13T00:00:00+00:00
[2023-03-01 12:03:39,486] {bash.py:135} INFO - Tmp dir root location: 
 /tmp
[2023-03-01 12:03:39,489] {bash.py:158} INFO - Running command: Hello Task 1
[2023-03-01 12:03:39,502] {bash.py:169} INFO - Output:
[2023-03-01 12:03:39,543] {bash.py:173} INFO - bash: Hello: command not found
[2023-03-01 12:03:39,546] {bash.py:177} INFO - Command exited with return code 127
[2023-03-01 12:03:39,572] {taskinstance.py:1482} ERROR - Task failed with exception
Traceback (most recent call last):
  File "/home/airflow/.local/lib/python3.6/site-packages/airflow/models/taskinstance.py", line 1138, in _run_raw_task
    self._prepare_and_execute_task_with_callbacks(context, task)
  File "/home/airflow/.local/lib/python3.6/site-packages/airflow/models/taskinstance.py", line 1311, in _prepare_and_execute_task_with_callbacks
    result = self._execute_task(context, task_copy)
  File "/home/airflow/.local/lib/python3.6/site-packages/airflow/models/taskinstance.py", line 1341, in _execute_task
    result = task_copy.execute(context=context)
  File "/home/airflow/.local/lib/python3.6/site-packages/airflow/operators/bash.py", line 180, in execute
    raise AirflowException('Bash command failed. The command returned a non-zero exit code.')
airflow.exceptions.AirflowException: Bash command failed. The command returned a non-zero exit code.
[2023-03-01 12:03:39,580] {taskinstance.py:1532} INFO - Marking task as UP_FOR_RETRY. dag_id=first_dag, task_id=task_1, execution_date=20210813T000000, start_date=20230301T120339, end_date=20230301T120339
[2023-03-01 12:03:39,670] {local_task_job.py:146} INFO - Task exited with return code 1
