[2023-03-01 12:10:54,618] {taskinstance.py:877} INFO - Dependencies all met for <TaskInstance: first_dag.task_1 2021-08-13T00:00:00+00:00 [queued]>
[2023-03-01 12:10:54,750] {taskinstance.py:877} INFO - Dependencies all met for <TaskInstance: first_dag.task_1 2021-08-13T00:00:00+00:00 [queued]>
[2023-03-01 12:10:54,760] {taskinstance.py:1068} INFO - 
--------------------------------------------------------------------------------
[2023-03-01 12:10:54,762] {taskinstance.py:1069} INFO - Starting attempt 6 of 6
[2023-03-01 12:10:54,763] {taskinstance.py:1070} INFO - 
--------------------------------------------------------------------------------
[2023-03-01 12:10:54,924] {taskinstance.py:1089} INFO - Executing <Task(BashOperator): task_1> on 2021-08-13T00:00:00+00:00
[2023-03-01 12:10:54,951] {standard_task_runner.py:52} INFO - Started process 1363 to run task
[2023-03-01 12:10:55,013] {standard_task_runner.py:76} INFO - Running: ['airflow', 'tasks', 'run', 'first_dag', 'task_1', '2021-08-13T00:00:00+00:00', '--job-id', '213', '--pool', 'default_pool', '--raw', '--subdir', 'DAGS_FOLDER/01_hello.py', '--cfg-path', '/tmp/tmp5vkxxkka', '--error-file', '/tmp/tmp6yexj116']
[2023-03-01 12:10:55,023] {standard_task_runner.py:77} INFO - Job 213: Subtask task_1
[2023-03-01 12:10:55,852] {logging_mixin.py:104} INFO - Running <TaskInstance: first_dag.task_1 2021-08-13T00:00:00+00:00 [running]> on host abe4c4997ef7
[2023-03-01 12:10:56,255] {taskinstance.py:1283} INFO - Exporting the following env vars:
AIRFLOW_CTX_DAG_OWNER=dataheroes
AIRFLOW_CTX_DAG_ID=first_dag
AIRFLOW_CTX_TASK_ID=task_1
AIRFLOW_CTX_EXECUTION_DATE=2021-08-13T00:00:00+00:00
AIRFLOW_CTX_DAG_RUN_ID=scheduled__2021-08-13T00:00:00+00:00
[2023-03-01 12:10:56,260] {bash.py:135} INFO - Tmp dir root location: 
 /tmp
[2023-03-01 12:10:56,295] {bash.py:158} INFO - Running command: Hello Task 1
[2023-03-01 12:10:56,418] {bash.py:169} INFO - Output:
[2023-03-01 12:10:56,648] {bash.py:173} INFO - bash: Hello: command not found
[2023-03-01 12:10:56,668] {bash.py:177} INFO - Command exited with return code 127
[2023-03-01 12:10:56,935] {taskinstance.py:1482} ERROR - Task failed with exception
Traceback (most recent call last):
  File "/home/airflow/.local/lib/python3.6/site-packages/airflow/models/taskinstance.py", line 1138, in _run_raw_task
    self._prepare_and_execute_task_with_callbacks(context, task)
  File "/home/airflow/.local/lib/python3.6/site-packages/airflow/models/taskinstance.py", line 1311, in _prepare_and_execute_task_with_callbacks
    result = self._execute_task(context, task_copy)
  File "/home/airflow/.local/lib/python3.6/site-packages/airflow/models/taskinstance.py", line 1341, in _execute_task
    result = task_copy.execute(context=context)
  File "/home/airflow/.local/lib/python3.6/site-packages/airflow/operators/bash.py", line 180, in execute
    raise AirflowException('Bash command failed. The command returned a non-zero exit code.')
airflow.exceptions.AirflowException: Bash command failed. The command returned a non-zero exit code.
[2023-03-01 12:10:57,015] {taskinstance.py:1532} INFO - Marking task as FAILED. dag_id=first_dag, task_id=task_1, execution_date=20210813T000000, start_date=20230301T121054, end_date=20230301T121056
[2023-03-01 12:10:57,315] {local_task_job.py:146} INFO - Task exited with return code 1
