[2023-03-01 12:10:57,182] {taskinstance.py:877} INFO - Dependencies all met for <TaskInstance: first_dag.task_3 2021-08-08T00:00:00+00:00 [queued]>
[2023-03-01 12:10:57,460] {taskinstance.py:877} INFO - Dependencies all met for <TaskInstance: first_dag.task_3 2021-08-08T00:00:00+00:00 [queued]>
[2023-03-01 12:10:57,469] {taskinstance.py:1068} INFO - 
--------------------------------------------------------------------------------
[2023-03-01 12:10:57,476] {taskinstance.py:1069} INFO - Starting attempt 3 of 6
[2023-03-01 12:10:57,479] {taskinstance.py:1070} INFO - 
--------------------------------------------------------------------------------
[2023-03-01 12:10:57,616] {taskinstance.py:1089} INFO - Executing <Task(BashOperator): task_3> on 2021-08-08T00:00:00+00:00
[2023-03-01 12:10:57,623] {standard_task_runner.py:52} INFO - Started process 1385 to run task
[2023-03-01 12:10:57,682] {standard_task_runner.py:76} INFO - Running: ['airflow', 'tasks', 'run', 'first_dag', 'task_3', '2021-08-08T00:00:00+00:00', '--job-id', '217', '--pool', 'default_pool', '--raw', '--subdir', 'DAGS_FOLDER/01_hello.py', '--cfg-path', '/tmp/tmpxviylr9r', '--error-file', '/tmp/tmpflg2sibj']
[2023-03-01 12:10:57,702] {standard_task_runner.py:77} INFO - Job 217: Subtask task_3
[2023-03-01 12:10:58,409] {logging_mixin.py:104} INFO - Running <TaskInstance: first_dag.task_3 2021-08-08T00:00:00+00:00 [running]> on host abe4c4997ef7
[2023-03-01 12:10:58,855] {taskinstance.py:1283} INFO - Exporting the following env vars:
AIRFLOW_CTX_DAG_OWNER=dataheroes
AIRFLOW_CTX_DAG_ID=first_dag
AIRFLOW_CTX_TASK_ID=task_3
AIRFLOW_CTX_EXECUTION_DATE=2021-08-08T00:00:00+00:00
AIRFLOW_CTX_DAG_RUN_ID=scheduled__2021-08-08T00:00:00+00:00
[2023-03-01 12:10:58,866] {bash.py:135} INFO - Tmp dir root location: 
 /tmp
[2023-03-01 12:10:58,887] {bash.py:158} INFO - Running command: Hello Task 3
[2023-03-01 12:10:59,004] {bash.py:169} INFO - Output:
[2023-03-01 12:10:59,185] {bash.py:173} INFO - bash: Hello: command not found
[2023-03-01 12:10:59,198] {bash.py:177} INFO - Command exited with return code 127
[2023-03-01 12:10:59,290] {taskinstance.py:1482} ERROR - Task failed with exception
Traceback (most recent call last):
  File "/home/airflow/.local/lib/python3.6/site-packages/airflow/models/taskinstance.py", line 1138, in _run_raw_task
    self._prepare_and_execute_task_with_callbacks(context, task)
  File "/home/airflow/.local/lib/python3.6/site-packages/airflow/models/taskinstance.py", line 1311, in _prepare_and_execute_task_with_callbacks
    result = self._execute_task(context, task_copy)
  File "/home/airflow/.local/lib/python3.6/site-packages/airflow/models/taskinstance.py", line 1341, in _execute_task
    result = task_copy.execute(context=context)
  File "/home/airflow/.local/lib/python3.6/site-packages/airflow/operators/bash.py", line 180, in execute
    raise AirflowException('Bash command failed. The command returned a non-zero exit code.')
airflow.exceptions.AirflowException: Bash command failed. The command returned a non-zero exit code.
[2023-03-01 12:10:59,347] {taskinstance.py:1532} INFO - Marking task as UP_FOR_RETRY. dag_id=first_dag, task_id=task_3, execution_date=20210808T000000, start_date=20230301T121057, end_date=20230301T121059
[2023-03-01 12:10:59,612] {local_task_job.py:146} INFO - Task exited with return code 1
