[2023-03-01 08:10:09,544] {taskinstance.py:877} INFO - Dependencies all met for <TaskInstance: docker_operator_dag.docker_command_hello 2023-03-01T07:05:00+00:00 [queued]>
[2023-03-01 08:10:09,586] {taskinstance.py:877} INFO - Dependencies all met for <TaskInstance: docker_operator_dag.docker_command_hello 2023-03-01T07:05:00+00:00 [queued]>
[2023-03-01 08:10:09,587] {taskinstance.py:1068} INFO - 
--------------------------------------------------------------------------------
[2023-03-01 08:10:09,588] {taskinstance.py:1069} INFO - Starting attempt 2 of 2
[2023-03-01 08:10:09,589] {taskinstance.py:1070} INFO - 
--------------------------------------------------------------------------------
[2023-03-01 08:10:09,613] {taskinstance.py:1089} INFO - Executing <Task(DockerOperator): docker_command_hello> on 2023-03-01T07:05:00+00:00
[2023-03-01 08:10:09,618] {standard_task_runner.py:52} INFO - Started process 122 to run task
[2023-03-01 08:10:09,627] {standard_task_runner.py:76} INFO - Running: ['airflow', 'tasks', 'run', 'docker_operator_dag', 'docker_command_hello', '2023-03-01T07:05:00+00:00', '--job-id', '17', '--pool', 'default_pool', '--raw', '--subdir', 'DAGS_FOLDER/helloairflow/hello.py', '--cfg-path', '/tmp/tmp93b0xtlk', '--error-file', '/tmp/tmpeu23z1lf']
[2023-03-01 08:10:09,629] {standard_task_runner.py:77} INFO - Job 17: Subtask docker_command_hello
[2023-03-01 08:10:09,736] {logging_mixin.py:104} INFO - Running <TaskInstance: docker_operator_dag.docker_command_hello 2023-03-01T07:05:00+00:00 [running]> on host d6ae11b410f8
[2023-03-01 08:10:09,839] {taskinstance.py:1283} INFO - Exporting the following env vars:
AIRFLOW_CTX_DAG_OWNER=Nama Masing Masing
AIRFLOW_CTX_DAG_ID=docker_operator_dag
AIRFLOW_CTX_TASK_ID=docker_command_hello
AIRFLOW_CTX_EXECUTION_DATE=2023-03-01T07:05:00+00:00
AIRFLOW_CTX_DAG_RUN_ID=scheduled__2023-03-01T07:05:00+00:00
[2023-03-01 08:10:09,866] {taskinstance.py:1482} ERROR - Task failed with exception
Traceback (most recent call last):
  File "/home/airflow/.local/lib/python3.6/site-packages/urllib3/connectionpool.py", line 677, in urlopen
    chunked=chunked,
  File "/home/airflow/.local/lib/python3.6/site-packages/urllib3/connectionpool.py", line 392, in _make_request
    conn.request(method, url, **httplib_request_kw)
  File "/usr/local/lib/python3.6/http/client.py", line 1291, in request
    self._send_request(method, url, body, headers, encode_chunked)
  File "/usr/local/lib/python3.6/http/client.py", line 1337, in _send_request
    self.endheaders(body, encode_chunked=encode_chunked)
  File "/usr/local/lib/python3.6/http/client.py", line 1286, in endheaders
    self._send_output(message_body, encode_chunked=encode_chunked)
  File "/usr/local/lib/python3.6/http/client.py", line 1046, in _send_output
    self.send(msg)
  File "/usr/local/lib/python3.6/http/client.py", line 984, in send
    self.connect()
  File "/home/airflow/.local/lib/python3.6/site-packages/docker/transport/unixconn.py", line 43, in connect
    sock.connect(self.unix_socket)
PermissionError: [Errno 13] Permission denied

During handling of the above exception, another exception occurred:

Traceback (most recent call last):
  File "/home/airflow/.local/lib/python3.6/site-packages/requests/adapters.py", line 449, in send
    timeout=timeout
  File "/home/airflow/.local/lib/python3.6/site-packages/urllib3/connectionpool.py", line 727, in urlopen
    method, url, error=e, _pool=self, _stacktrace=sys.exc_info()[2]
  File "/home/airflow/.local/lib/python3.6/site-packages/urllib3/util/retry.py", line 410, in increment
    raise six.reraise(type(error), error, _stacktrace)
  File "/home/airflow/.local/lib/python3.6/site-packages/urllib3/packages/six.py", line 734, in reraise
    raise value.with_traceback(tb)
  File "/home/airflow/.local/lib/python3.6/site-packages/urllib3/connectionpool.py", line 677, in urlopen
    chunked=chunked,
  File "/home/airflow/.local/lib/python3.6/site-packages/urllib3/connectionpool.py", line 392, in _make_request
    conn.request(method, url, **httplib_request_kw)
  File "/usr/local/lib/python3.6/http/client.py", line 1291, in request
    self._send_request(method, url, body, headers, encode_chunked)
  File "/usr/local/lib/python3.6/http/client.py", line 1337, in _send_request
    self.endheaders(body, encode_chunked=encode_chunked)
  File "/usr/local/lib/python3.6/http/client.py", line 1286, in endheaders
    self._send_output(message_body, encode_chunked=encode_chunked)
  File "/usr/local/lib/python3.6/http/client.py", line 1046, in _send_output
    self.send(msg)
  File "/usr/local/lib/python3.6/http/client.py", line 984, in send
    self.connect()
  File "/home/airflow/.local/lib/python3.6/site-packages/docker/transport/unixconn.py", line 43, in connect
    sock.connect(self.unix_socket)
urllib3.exceptions.ProtocolError: ('Connection aborted.', PermissionError(13, 'Permission denied'))

During handling of the above exception, another exception occurred:

Traceback (most recent call last):
  File "/home/airflow/.local/lib/python3.6/site-packages/docker/api/client.py", line 207, in _retrieve_server_version
    return self.version(api_version=False)["ApiVersion"]
  File "/home/airflow/.local/lib/python3.6/site-packages/docker/api/daemon.py", line 181, in version
    return self._result(self._get(url), json=True)
  File "/home/airflow/.local/lib/python3.6/site-packages/docker/utils/decorators.py", line 46, in inner
    return f(self, *args, **kwargs)
  File "/home/airflow/.local/lib/python3.6/site-packages/docker/api/client.py", line 230, in _get
    return self.get(url, **self._set_request_timeout(kwargs))
  File "/home/airflow/.local/lib/python3.6/site-packages/requests/sessions.py", line 555, in get
    return self.request('GET', url, **kwargs)
  File "/home/airflow/.local/lib/python3.6/site-packages/requests/sessions.py", line 542, in request
    resp = self.send(prep, **send_kwargs)
  File "/home/airflow/.local/lib/python3.6/site-packages/requests/sessions.py", line 655, in send
    r = adapter.send(request, **kwargs)
  File "/home/airflow/.local/lib/python3.6/site-packages/requests/adapters.py", line 498, in send
    raise ConnectionError(err, request=request)
requests.exceptions.ConnectionError: ('Connection aborted.', PermissionError(13, 'Permission denied'))

During handling of the above exception, another exception occurred:

Traceback (most recent call last):
  File "/home/airflow/.local/lib/python3.6/site-packages/airflow/models/taskinstance.py", line 1138, in _run_raw_task
    self._prepare_and_execute_task_with_callbacks(context, task)
  File "/home/airflow/.local/lib/python3.6/site-packages/airflow/models/taskinstance.py", line 1311, in _prepare_and_execute_task_with_callbacks
    result = self._execute_task(context, task_copy)
  File "/home/airflow/.local/lib/python3.6/site-packages/airflow/models/taskinstance.py", line 1341, in _execute_task
    result = task_copy.execute(context=context)
  File "/home/airflow/.local/lib/python3.6/site-packages/airflow/providers/docker/operators/docker.py", line 287, in execute
    self.cli = self._get_cli()
  File "/home/airflow/.local/lib/python3.6/site-packages/airflow/providers/docker/operators/docker.py", line 319, in _get_cli
    return APIClient(base_url=self.docker_url, version=self.api_version, tls=tls_config)
  File "/home/airflow/.local/lib/python3.6/site-packages/docker/api/client.py", line 190, in __init__
    self._version = self._retrieve_server_version()
  File "/home/airflow/.local/lib/python3.6/site-packages/docker/api/client.py", line 215, in _retrieve_server_version
    'Error while fetching server API version: {0}'.format(e)
docker.errors.DockerException: Error while fetching server API version: ('Connection aborted.', PermissionError(13, 'Permission denied'))
[2023-03-01 08:10:09,888] {taskinstance.py:1532} INFO - Marking task as FAILED. dag_id=docker_operator_dag, task_id=docker_command_hello, execution_date=20230301T070500, start_date=20230301T081009, end_date=20230301T081009
[2023-03-01 08:10:09,966] {local_task_job.py:146} INFO - Task exited with return code 1
