[2023-03-01 12:15:11,917] {taskinstance.py:877} INFO - Dependencies all met for <TaskInstance: first_dag.task_3 2021-08-07T00:00:00+00:00 [queued]>
[2023-03-01 12:15:12,221] {taskinstance.py:877} INFO - Dependencies all met for <TaskInstance: first_dag.task_3 2021-08-07T00:00:00+00:00 [queued]>
[2023-03-01 12:15:12,222] {taskinstance.py:1068} INFO - 
--------------------------------------------------------------------------------
[2023-03-01 12:15:12,223] {taskinstance.py:1069} INFO - Starting attempt 5 of 6
[2023-03-01 12:15:12,232] {taskinstance.py:1070} INFO - 
--------------------------------------------------------------------------------
[2023-03-01 12:15:12,413] {taskinstance.py:1089} INFO - Executing <Task(BashOperator): task_3> on 2021-08-07T00:00:00+00:00
[2023-03-01 12:15:12,456] {standard_task_runner.py:76} INFO - Running: ['airflow', 'tasks', 'run', 'first_dag', 'task_3', '2021-08-07T00:00:00+00:00', '--job-id', '457', '--pool', 'default_pool', '--raw', '--subdir', 'DAGS_FOLDER/01_hello.py', '--cfg-path', '/tmp/tmpo3uadzvm', '--error-file', '/tmp/tmpuzlopw42']
[2023-03-01 12:15:12,476] {standard_task_runner.py:77} INFO - Job 457: Subtask task_3
[2023-03-01 12:15:12,441] {standard_task_runner.py:52} INFO - Started process 2510 to run task
[2023-03-01 12:15:12,789] {logging_mixin.py:104} INFO - Running <TaskInstance: first_dag.task_3 2021-08-07T00:00:00+00:00 [running]> on host abe4c4997ef7
[2023-03-01 12:15:13,057] {taskinstance.py:1283} INFO - Exporting the following env vars:
AIRFLOW_CTX_DAG_OWNER=dataheroes
AIRFLOW_CTX_DAG_ID=first_dag
AIRFLOW_CTX_TASK_ID=task_3
AIRFLOW_CTX_EXECUTION_DATE=2021-08-07T00:00:00+00:00
AIRFLOW_CTX_DAG_RUN_ID=scheduled__2021-08-07T00:00:00+00:00
[2023-03-01 12:15:13,062] {bash.py:135} INFO - Tmp dir root location: 
 /tmp
[2023-03-01 12:15:13,071] {bash.py:158} INFO - Running command: Hello Task 3
[2023-03-01 12:15:13,137] {bash.py:169} INFO - Output:
[2023-03-01 12:15:13,249] {bash.py:173} INFO - bash: Hello: command not found
[2023-03-01 12:15:13,285] {bash.py:177} INFO - Command exited with return code 127
[2023-03-01 12:15:13,378] {taskinstance.py:1482} ERROR - Task failed with exception
Traceback (most recent call last):
  File "/home/airflow/.local/lib/python3.6/site-packages/airflow/models/taskinstance.py", line 1138, in _run_raw_task
    self._prepare_and_execute_task_with_callbacks(context, task)
  File "/home/airflow/.local/lib/python3.6/site-packages/airflow/models/taskinstance.py", line 1311, in _prepare_and_execute_task_with_callbacks
    result = self._execute_task(context, task_copy)
  File "/home/airflow/.local/lib/python3.6/site-packages/airflow/models/taskinstance.py", line 1341, in _execute_task
    result = task_copy.execute(context=context)
  File "/home/airflow/.local/lib/python3.6/site-packages/airflow/operators/bash.py", line 180, in execute
    raise AirflowException('Bash command failed. The command returned a non-zero exit code.')
airflow.exceptions.AirflowException: Bash command failed. The command returned a non-zero exit code.
[2023-03-01 12:15:13,416] {taskinstance.py:1532} INFO - Marking task as UP_FOR_RETRY. dag_id=first_dag, task_id=task_3, execution_date=20210807T000000, start_date=20230301T121511, end_date=20230301T121513
[2023-03-01 12:15:13,726] {local_task_job.py:146} INFO - Task exited with return code 1
